Workbook

Sheet 01_習慣設計
A1: 01_習慣設計
A2: 目的：最初に、学ぶ理由・習慣化の4法則・ご褒美・リカバリールールを決める。ここは毎日触る場所ではなく、迷った時に戻る土台です。
A4: 初期設定 | F4: 3週間・3ヶ月ライン
A5: 項目 | B5: 値 | C5: 補足 | F5: ライン | G5: 目的 | H5: 見るポイント
A6: 開始日 | B6: 46204 | C6: この日から2年分を記録します | F6: 3週間 | G6: 脳に慣れさせる | H6: 完璧ではなく毎日少し触れる。1行だけでも前進。
A7: 終了日 | B7: 46934 | C7: 2028年6月30日まで記録します | F7: 3ヶ月 | G7: 自分の習慣として定着させる | H7: 2日連続で完全に離れない。崩れたら小さく戻る。
A8: 記録日数 | B8: =B7-B6+1 -> 731 | C8: 開始日〜終了日までの日数
A9: 週の学習予定時間（分） | B9: ='02_週間時間割'!Q7 -> 210 | C9: 02_週間時間割で「学習」と入力したセル数 × 30分
A11: 目標宣言｜自分の回答欄を埋める
A12: 項目 | B12: 自分の回答 | C12: 記入例 | D12: 書き方のコツ
A13: 私が学ぶ理由 | C13: AI時代に、自分で考え、作り、仕事に活かせる力をつけたい。 | D13: きれいな言葉より、自分の本音を書く
A14: 3ヶ月後にできるようになりたいこと | C14: PC操作とAI活用に慣れ、日々の仕事の小さな作業を楽にできる。 | D14: 近いゴール。小さくてOK
A15: 6ヶ月後にできるようになりたいこと | C15: 自分のLP/HPを公開し、AIチームの基本的な使い方を身につける。 | D15: ロードマップ前半の到達点
A16: 1年後に目指したい状態 | C16: 自分で調べ、AIに相談しながら、簡単な業務改善を進められる。 | D16: 仕事や生活にどう活かすかを書く
A17: 2年後に目指したい状態 | C17: 自分の仕事・事業・学びにAIを自然に組み込み、価値提供できる。 | D17: 長期の理想像を書く
A19: 習慣化の4法則｜続けるための自分ルールを作る
A20: 法則 | B20: 自分のルール | C20: 記入例 | D20: 補足
A21: 1. はっきりさせる | C21: 朝6時に机でPCを開き、教材を5分だけ進める。 | D21: いつ・どこで・何をやるかを決める。曖昧な「勉強する」ではなく、行動が見える形にする。
A22: 2. 魅力的にする | C22: AIを使って仕事や事業を進められるようになる。1週間頑張ったら好きなカフェに行く。 | D22: 続けるメリットと、ご褒美・楽しみを書く。しんどい時に「なぜ学ぶのか」と「続けた先の楽しみ」を思い出せるようにする。
A23: 3. 簡単にする | C23: 疲れた日はシートに一言だけ書けばOK。教材を1ページ開くだけでもOK。 | D23: 最初は成果より回数。ゼロにしない最低ラインを決める。
A24: 4. 記録を取る | C24: 学習時間、今日のふりかえり、詰まったことを残す。 | D24: 記録は責めるためではなく、前進している感覚を持つために使う。記録を見返して満足できるようにする。
A27: リカバリールール｜予定が崩れたときに戻るための設計
A28: 場面 | B28: 自分のルール | C28: 記入例 | D28: 日々の記録に書く例
A29: 急な予定が入った | C29: 予定を責めず、夜に1行だけ記録する。 | D29: 急な予定でできなかった。明日は5分だけ開く。
A30: 疲れている | C30: 学習を無理に進めず、休憩を優先して一言だけ書く。 | D30: 今日は疲れていたので休む。明日は教材を1ページ開く。
A31: 挫折しそう | C31: 教材を進めず、目標宣言を読み返すだけでOK。 | D31: 少ししんどい。明日は目標を読み返すところから戻る。
A32: 3日空いた | C32: 遅れを取り返そうとせず、次の日は5分だけにする。 | D32: 3日空いた。明日は5分だけPCを開く。
A33: 1週間空いた | C33: 週間時間割を作り直す。できなかった理由を責めずに見る。 | D33: 1週間空いたので、今週の時間割を作り直す。
A34: 詰まって止まった | C34: 詰まったことを1行書き、質問する前提にする。 | D34: ここで詰まった。次回ここを質問する。

Sheet 02_週間時間割
A1: 02_週間時間割
A3: 週間時間割｜0:00〜24:00を30分単位で可視化する | J3: 時間割カテゴリ・色ルール | O3: 週間時間割の自動集計
A4: 時間 | B4: 月 | C4: 火 | D4: 水 | E4: 木 | F4: 金 | G4: 土 | H4: 日 | J4: カテゴリ | K4: 用途 | L4: 色 | M4: 入力方法 | O4: カテゴリ | P4: セル数 | Q4: 予定時間（分） | R4: 予定時間（時間）
A5: 00:00 | B5: 睡眠 | C5: 睡眠 | D5: 睡眠 | E5: 睡眠 | F5: 睡眠 | G5: 睡眠 | H5: 睡眠 | J5: 睡眠 | K5: 寝る時間 | L5: 灰色 | M5: セルに「睡眠」と入力 | O5: 睡眠 | P5: =COUNTIF($B$5:$H$52,O5) -> 112 | Q5: =P5*30 -> 3360 | R5: =Q5/60 -> 56
A6: 00:30 | B6: 睡眠 | C6: 睡眠 | D6: 睡眠 | E6: 睡眠 | F6: 睡眠 | G6: 睡眠 | H6: 睡眠 | J6: 仕事 | K6: 本業・仕事時間 | L6: 緑 | M6: セルに「仕事」と入力 | O6: 仕事 | P6: =COUNTIF($B$5:$H$52,O6) -> 80 | Q6: =P6*30 -> 2400 | R6: =Q6/60 -> 40
A7: 01:00 | B7: 睡眠 | C7: 睡眠 | D7: 睡眠 | E7: 睡眠 | F7: 睡眠 | G7: 睡眠 | H7: 睡眠 | J7: 学習 | K7: 必ず学習に当てる時間 | L7: 濃い青 | M7: セルに「学習」と入力 | O7: 学習 | P7: =COUNTIF($B$5:$H$52,O7) -> 7 | Q7: =P7*30 -> 210 | R7: =Q7/60 -> 3.5
A8: 01:30 | B8: 睡眠 | C8: 睡眠 | D8: 睡眠 | E8: 睡眠 | F8: 睡眠 | G8: 睡眠 | H8: 睡眠 | J8: 家事 | K8: 家事、身支度、食事準備など | L8: 濃いオレンジ | M8: セルに「家事」と入力 | O8: 家事 | P8: =COUNTIF($B$5:$H$52,O8) -> 35 | Q8: =P8*30 -> 1050 | R8: =Q8/60 -> 17.5
A9: 02:00 | B9: 睡眠 | C9: 睡眠 | D9: 睡眠 | E9: 睡眠 | F9: 睡眠 | G9: 睡眠 | H9: 睡眠 | J9: 移動 | K9: 通勤、移動、外出までの時間 | L9: 淡い黄色 | M9: セルに「移動」と入力 | O9: 移動 | P9: =COUNTIF($B$5:$H$52,O9) -> 20 | Q9: =P9*30 -> 600 | R9: =Q9/60 -> 10
A10: 02:30 | B10: 睡眠 | C10: 睡眠 | D10: 睡眠 | E10: 睡眠 | F10: 睡眠 | G10: 睡眠 | H10: 睡眠 | J10: 趣味 | K10: 好きなこと、娯楽 | L10: 淡い紫 | M10: セルに「趣味」と入力 | O10: 趣味 | P10: =COUNTIF($B$5:$H$52,O10) -> 61 | Q10: =P10*30 -> 1830 | R10: =Q10/60 -> 30.5
A11: 03:00 | B11: 睡眠 | C11: 睡眠 | D11: 睡眠 | E11: 睡眠 | F11: 睡眠 | G11: 睡眠 | H11: 睡眠 | J11: 休憩 | K11: 何もしない、休む | L11: 白（文字で判別） | M11: セルに「休憩」と入力 | O11: 休憩 | P11: =COUNTIF($B$5:$H$52,O11) -> 21 | Q11: =P11*30 -> 630 | R11: =Q11/60 -> 10.5
A12: 03:30 | B12: 睡眠 | C12: 睡眠 | D12: 睡眠 | E12: 睡眠 | F12: 睡眠 | G12: 睡眠 | H12: 睡眠 | J12: 空欄 | K12: 予定なし・空いている時間 | L12: 白（何も入力しない） | M12: 何も入力しない | O12: 空欄 | P12: =COUNTBLANK($B$5:$H$52) -> 0 | Q12: =P12*30 -> 0 | R12: =Q12/60 -> 0
A13: 04:00 | B13: 睡眠 | C13: 睡眠 | D13: 睡眠 | E13: 睡眠 | F13: 睡眠 | G13: 睡眠 | H13: 睡眠
A14: 04:30 | B14: 睡眠 | C14: 睡眠 | D14: 睡眠 | E14: 睡眠 | F14: 睡眠 | G14: 睡眠 | H14: 睡眠
A15: 05:00 | B15: 睡眠 | C15: 睡眠 | D15: 睡眠 | E15: 睡眠 | F15: 睡眠 | G15: 睡眠 | H15: 睡眠
A16: 05:30 | B16: 睡眠 | C16: 睡眠 | D16: 睡眠 | E16: 睡眠 | F16: 睡眠 | G16: 睡眠 | H16: 睡眠
A17: 06:00 | B17: 学習 | C17: 学習 | D17: 学習 | E17: 学習 | F17: 学習 | G17: 学習 | H17: 学習
A18: 06:30 | B18: 家事 | C18: 家事 | D18: 家事 | E18: 家事 | F18: 家事 | G18: 家事 | H18: 家事
A19: 07:00 | B19: 家事 | C19: 家事 | D19: 家事 | E19: 家事 | F19: 家事 | G19: 家事 | H19: 家事
A20: 07:30 | B20: 移動 | C20: 移動 | D20: 移動 | E20: 移動 | F20: 移動 | G20: 趣味 | H20: 趣味
A21: 08:00 | B21: 移動 | C21: 移動 | D21: 移動 | E21: 移動 | F21: 移動 | G21: 趣味 | H21: 趣味
A22: 08:30 | B22: 移動 | C22: 移動 | D22: 移動 | E22: 移動 | F22: 移動 | G22: 趣味 | H22: 趣味
A23: 09:00 | B23: 移動 | C23: 移動 | D23: 移動 | E23: 移動 | F23: 移動 | G23: 趣味 | H23: 趣味
A24: 09:30 | B24: 仕事 | C24: 仕事 | D24: 仕事 | E24: 仕事 | F24: 仕事 | G24: 趣味 | H24: 趣味
... A52: 23:30 | B52: 睡眠 | C52: 睡眠 | D52: 睡眠 | E52: 睡眠 | F52: 睡眠 | G52: 睡眠 | H52: 睡眠

Sheet 03_日々の記録
A1: 03_日々の記録
A2: 目的：毎日の入力は「学習時間（分）」「今日のふりかえり・明日の一歩」「詰まったこと」の3つだけ。記録は自分を責めるためではなく、前進を見える化するために使います。
A4: 自動集計
A5: 累計記録日数 | B5: 累計学習時間（分） | C5: 累計学習時間（時間） | D5: 今週の記録日数 | E5: 今週の学習時間（分） | F5: 直近7日の記録日数 | G5: 今月の記録日数 | H5: 記録率
A6: =SUM(H12:H742) -> 1 | B6: =SUM(E12:E742) -> 44 | C6: =B6/60 -> 0.73333333 | D6: =SUMIFS(H12:H742,A12:A742,">="&TODAY()-WEEKDAY(TODAY(),2)+1,A12:A742,"<="&TODAY()) -> 0 | E6: =SUMIFS(E12:E742,A12:A742,">="&TODAY()-WEEKDAY(TODAY(),2)+1,A12:A742,"<="&TODAY()) -> 0 | F6: =SUMIFS(H12:H742,A12:A742,">="&TODAY()-6,A12:A742,"<="&TODAY()) -> 0 | G6: =SUMIFS(H12:H742,A12:A742,">="&EOMONTH(TODAY(),-1)+1,A12:A742,"<="&TODAY()) -> 0 | H6: =IF(COUNT(A12:A742)=0,0,A6/COUNT(A12:A742)) -> 0.0013679891
E8: 入力例
E9: 30 | F9: 第5章を進めた。明日は目標宣言を読み返す。 | G9: 時間割の作り方が少し曖昧。
E10: 0 | F10: 今日はできなかった。明日は5分だけPCを開く。 | G10: 仕事で疲れていた。
A11: 日付 | B11: 曜日 | C11: 何週目 | D11: 何ヶ月目 | E11: 学習時間（分） | F11: 今日のふりかえり・明日の一歩 | G11: 詰まったこと | H11: 記録済み
A12: 46204 | B12: =CHOOSE(WEEKDAY(A12,2),"月","火","水","木","金","土","日") -> 水 | C12: =ROUNDUP((A12-'01_習慣設計'!$B$6+1)/7,0) -> 1 | D12: =(YEAR(A12)-YEAR('01_習慣設計'!$B$6))*12+MONTH(A12)-MONTH('01_習慣設計'!$B$6)+1 -> 1 | E12: 44 | H12: =IF(OR(E12>0,LEN(F12)>0,LEN(G12)>0),1,0) -> 1
A13: 46205 | B13: =CHOOSE(WEEKDAY(A13,2),"月","火","水","木","金","土","日") -> 木 | C13: =ROUNDUP((A13-'01_習慣設計'!$B$6+1)/7,0) -> 1 | D13: =(YEAR(A13)-YEAR('01_習慣設計'!$B$6))*12+MONTH(A13)-MONTH('01_習慣設計'!$B$6)+1 -> 1 | H13: =IF(OR(E13>0,LEN(F13)>0,LEN(G13)>0),1,0) -> 0
A14: 46206 | B14: =CHOOSE(WEEKDAY(A14,2),"月","火","水","木","金","土","日") -> 金 | C14: =ROUNDUP((A14-'01_習慣設計'!$B$6+1)/7,0) -> 1 | D14: =(YEAR(A14)-YEAR('01_習慣設計'!$B$6))*12+MONTH(A14)-MONTH('01_習慣設計'!$B$6)+1 -> 1 | H14: =IF(OR(E14>0,LEN(F14)>0,LEN(G14)>0),1,0) -> 0
A15: 46207 | B15: =CHOOSE(WEEKDAY(A15,2),"月","火","水","木","金","土","日") -> 土 | C15: =ROUNDUP((A15-'01_習慣設計'!$B$6+1)/7,0) -> 1 | D15: =(YEAR(A15)-YEAR('01_習慣設計'!$B$6))*12+MONTH(A15)-MONTH('01_習慣設計'!$B$6)+1 -> 1 | H15: =IF(OR(E15>0,LEN(F15)>0,LEN(G15)>0),1,0) -> 0
A16: 46208 | B16: =CHOOSE(WEEKDAY(A16,2),"月","火","水","木","金","土","日") -> 日 | C16: =ROUNDUP((A16-'01_習慣設計'!$B$6+1)/7,0) -> 1 | D16: =(YEAR(A16)-YEAR('01_習慣設計'!$B$6))*12+MONTH(A16)-MONTH('01_習慣設計'!$B$6)+1 -> 1 | H16: =IF(OR(E16>0,LEN(F16)>0,LEN(G16)>0),1,0) -> 0
A17: 46209 | B17: =CHOOSE(WEEKDAY(A17,2),"月","火","水","木","金","土","日") -> 月 | C17: =ROUNDUP((A17-'01_習慣設計'!$B$6+1)/7,0) -> 1 | D17: =(YEAR(A17)-YEAR('01_習慣設計'!$B$6))*12+MONTH(A17)-MONTH('01_習慣設計'!$B$6)+1 -> 1 | H17: =IF(OR(E17>0,LEN(F17)>0,LEN(G17)>0),1,0) -> 0
A18: 46210 | B18: =CHOOSE(WEEKDAY(A18,2),"月","火","水","木","金","土","日") -> 火 | C18: =ROUNDUP((A18-'01_習慣設計'!$B$6+1)/7,0) -> 1 | D18: =(YEAR(A18)-YEAR('01_習慣設計'!$B$6))*12+MONTH(A18)-MONTH('01_習慣設計'!$B$6)+1 -> 1 | H18: =IF(OR(E18>0,LEN(F18)>0,LEN(G18)>0),1,0) -> 0
A19: 46211 | B19: =CHOOSE(WEEKDAY(A19,2),"月","火","水","木","金","土","日") -> 水 | C19: =ROUNDUP((A19-'01_習慣設計'!$B$6+1)/7,0) -> 2 | D19: =(YEAR(A19)-YEAR('01_習慣設計'!$B$6))*12+MONTH(A19)-MONTH('01_習慣設計'!$B$6)+1 -> 1 | H19: =IF(OR(E19>0,LEN(F19)>0,LEN(G19)>0),1,0) -> 0
A20: 46212 | B20: =CHOOSE(WEEKDAY(A20,2),"月","火","水","木","金","土","日") -> 木 | C20: =ROUNDUP((A20-'01_習慣設計'!$B$6+1)/7,0) -> 2 | D20: =(YEAR(A20)-YEAR('01_習慣設計'!$B$6))*12+MONTH(A20)-MONTH('01_習慣設計'!$B$6)+1 -> 1 | H20: =IF(OR(E20>0,LEN(F20)>0,LEN(G20)>0),1,0) -> 0
A21: 46213 | B21: =CHOOSE(WEEKDAY(A21,2),"月","火","水","木","金","土","日") -> 金 | C21: =ROUNDUP((A21-'01_習慣設計'!$B$6+1)/7,0) -> 2 | D21: =(YEAR(A21)-YEAR('01_習慣設計'!$B$6))*12+MONTH(A21)-MONTH('01_習慣設計'!$B$6)+1 -> 1 | H21: =IF(OR(E21>0,LEN(F21)>0,LEN(G21)>0),1,0) -> 0
A22: 46214 | B22: =CHOOSE(WEEKDAY(A22,2),"月","火","水","木","金","土","日") -> 土 | C22: =ROUNDUP((A22-'01_習慣設計'!$B$6+1)/7,0) -> 2 | D22: =(YEAR(A22)-YEAR('01_習慣設計'!$B$6))*12+MONTH(A22)-MONTH('01_習慣設計'!$B$6)+1 -> 1 | H22: =IF(OR(E22>0,LEN(F22)>0,LEN(G22)>0),1,0) -> 0
A23: 46215 | B23: =CHOOSE(WEEKDAY(A23,2),"月","火","水","木","金","土","日") -> 日 | C23: =ROUNDUP((A23-'01_習慣設計'!$B$6+1)/7,0) -> 2 | D23: =(YEAR(A23)-YEAR('01_習慣設計'!$B$6))*12+MONTH(A23)-MONTH('01_習慣設計'!$B$6)+1 -> 1 | H23: =IF(OR(E23>0,LEN(F23)>0,LEN(G23)>0),1,0) -> 0
A24: 46216 | B24: =CHOOSE(WEEKDAY(A24,2),"月","火","水","木","金","土","日") -> 月 | C24: =ROUNDUP((A24-'01_習慣設計'!$B$6+1)/7,0) -> 2 | D24: =(YEAR(A24)-YEAR('01_習慣設計'!$B$6))*12+MONTH(A24)-MONTH('01_習慣設計'!$B$6)+1 -> 1 | H24: =IF(OR(E24>0,LEN(F24)>0,LEN(G24)>0),1,0) -> 0
... A742: 46934 | B742: =CHOOSE(WEEKDAY(A742,2),"月","火","水","木","金","土","日") -> 金 | C742: =ROUNDUP((A742-'01_習慣設計'!$B$6+1)/7,0) -> 105 | D742: =(YEAR(A742)-YEAR('01_習慣設計'!$B$6))*12+MONTH(A742)-MONTH('01_習慣設計'!$B$6)+1 -> 24 | H742: =IF(OR(E742>0,LEN(F742)>0,LEN(G742)>0),1,0) -> 0

Sheet 04_行動変容ワーク
A1: 04_行動変容ワーク｜必要なところだけ使う道具箱
A2: このシートは提出物ではありません。毎日すべて埋める必要もありません。自分の行動を変えたい時、学習が止まりそうな時、考えすぎて動けない時に、必要なブロックだけ使ってください。書くほど「なぜ止まるのか」「どう戻るか」「次に何をするか」が見えやすくなります。
A5: 使い方｜上から順番に全部埋めなくてOK。必要なところだけ使う。
A6: 使う場面 | B6: おすすめブロック | C6: 使い方
A7: 何から始めればいいかわからない | B7: 1・2・3 | C7: 変えたい行動を1つ決め、止まる原因を選び、最初の2分に小さくする
A8: 疲れ・迷い・考えすぎで止まる | B8: 2・4・5 | C8: 止まる原因を選び、if-thenと戻り方を決める
A9: 時間の使い方を見直したい | B9: 重要×緊急マトリクス | C9: 今やっていることを4象限に仕分けし、第2領域に時間を寄せる
A11: 重要×緊急マトリクス｜自分の行動を仕分けして、第2領域に時間を寄せる
A12: 目的：今やっていることを「重要か」「緊急か」で分け、緊急ではないが重要な行動（第2領域）に時間を割けるようにする。第2領域は、学習・健康・仕組み化・準備・関係づくりなど、未来を良くする行動です。
B14: 緊急ではない | C14: 緊急
A15: 重要 | B15: 第2領域｜増やす 学習 / 健康 / 仕組み化 / 準備 / 関係づくり → 最初に予定へ入れる | C15: 第1領域｜減らす・予防する 締切 / トラブル / クレーム / 緊急対応 → 早めの仕組み化で減らす
A16: 重要ではない | B16: 第4領域｜減らす・やめる 惰性SNS / 目的のない動画 / なんとなく作業 → 先に削る | C16: 第3領域｜任せる・断る 急な依頼 / 通知 / 他人都合の割り込み → 断る・任せる・後に回す
A18: 行動の棚卸し｜今やっていることを4象限へ当てはめる
A19: やっていること | B19: 重要? | C19: 緊急? | D19: 象限（自動） | E19: 次の扱い（自動） | F19: メモ / 次の一歩
D20: =IF($A20="","",IFS(AND($B20="重要",$C20="緊急"),"第1領域｜重要×緊急",AND($B20="重要",$C20="緊急ではない"),"第2領域｜重要×非緊急",AND($B20="重要ではない",$C20="緊急"),"第3領域｜非重要×緊急",AND($B20="重要ではない",$C20="緊急ではない"),"第4領域｜非重要×非緊急",TRUE,"未分類")) | E20: =IF($A20="","",IFS(LEFT($D20,4)="第1領域","予防・仕組み化で減らす",LEFT($D20,4)="第2領域","先に予定へ入れて増やす",LEFT($D20,4)="第3領域","断る・任せる・後に回す",LEFT($D20,4)="第4領域","減らす・やめる",TRUE,"判断する"))
D21: =IF($A21="","",IFS(AND($B21="重要",$C21="緊急"),"第1領域｜重要×緊急",AND($B21="重要",$C21="緊急ではない"),"第2領域｜重要×非緊急",AND($B21="重要ではない",$C21="緊急"),"第3領域｜非重要×緊急",AND($B21="重要ではない",$C21="緊急ではない"),"第4領域｜非重要×非緊急",TRUE,"未分類")) | E21: =IF($A21="","",IFS(LEFT($D21,4)="第1領域","予防・仕組み化で減らす",LEFT($D21,4)="第2領域","先に予定へ入れて増やす",LEFT($D21,4)="第3領域","断る・任せる・後に回す",LEFT($D21,4)="第4領域","減らす・やめる",TRUE,"判断する"))
D22: =IF($A22="","",IFS(AND($B22="重要",$C22="緊急"),"第1領域｜重要×緊急",AND($B22="重要",$C22="緊急ではない"),"第2領域｜重要×非緊急",AND($B22="重要ではない",$C22="緊急"),"第3領域｜非重要×緊急",AND($B22="重要ではない",$C22="緊急ではない"),"第4領域｜非重要×非緊急",TRUE,"未分類")) | E22: =IF($A22="","",IFS(LEFT($D22,4)="第1領域","予防・仕組み化で減らす",LEFT($D22,4)="第2領域","先に予定へ入れて増やす",LEFT($D22,4)="第3領域","断る・任せる・後に回す",LEFT($D22,4)="第4領域","減らす・やめる",TRUE,"判断する"))
D23: =IF($A23="","",IFS(AND($B23="重要",$C23="緊急"),"第1領域｜重要×緊急",AND($B23="重要",$C23="緊急ではない"),"第2領域｜重要×非緊急",AND($B23="重要ではない",$C23="緊急"),"第3領域｜非重要×緊急",AND($B23="重要ではない",$C23="緊急ではない"),"第4領域｜非重要×非緊急",TRUE,"未分類")) | E23: =IF($A23="","",IFS(LEFT($D23,4)="第1領域","予防・仕組み化で減らす",LEFT($D23,4)="第2領域","先に予定へ入れて増やす",LEFT($D23,4)="第3領域","断る・任せる・後に回す",LEFT($D23,4)="第4領域","減らす・やめる",TRUE,"判断する"))
D24: =IF($A24="","",IFS(AND($B24="重要",$C24="緊急"),"第1領域｜重要×緊急",AND($B24="重要",$C24="緊急ではない"),"第2領域｜重要×非緊急",AND($B24="重要ではない",$C24="緊急"),"第3領域｜非重要×緊急",AND($B24="重要ではない",$C24="緊急ではない"),"第4領域｜非重要×非緊急",TRUE,"未分類")) | E24: =IF($A24="","",IFS(LEFT($D24,4)="第1領域","予防・仕組み化で減らす",LEFT($D24,4)="第2領域","先に予定へ入れて増やす",LEFT($D24,4)="第3領域","断る・任せる・後に回す",LEFT($D24,4)="第4領域","減らす・やめる",TRUE,"判断する"))
D25: =IF($A25="","",IFS(AND($B25="重要",$C25="緊急"),"第1領域｜重要×緊急",AND($B25="重要",$C25="緊急ではない"),"第2領域｜重要×非緊急",AND($B25="重要ではない",$C25="緊急"),"第3領域｜非重要×緊急",AND($B25="重要ではない",$C25="緊急ではない"),"第4領域｜非重要×非緊急",TRUE,"未分類")) | E25: =IF($A25="","",IFS(LEFT($D25,4)="第1領域","予防・仕組み化で減らす",LEFT($D25,4)="第2領域","先に予定へ入れて増やす",LEFT($D25,4)="第3領域","断る・任せる・後に回す",LEFT($D25,4)="第4領域","減らす・やめる",TRUE,"判断する"))
D26: =IF($A26="","",IFS(AND($B26="重要",$C26="緊急"),"第1領域｜重要×緊急",AND($B26="重要",$C26="緊急ではない"),"第2領域｜重要×非緊急",AND($B26="重要ではない",$C26="緊急"),"第3領域｜非重要×緊急",AND($B26="重要ではない",$C26="緊急ではない"),"第4領域｜非重要×非緊急",TRUE,"未分類")) | E26: =IF($A26="","",IFS(LEFT($D26,4)="第1領域","予防・仕組み化で減らす",LEFT($D26,4)="第2領域","先に予定へ入れて増やす",LEFT($D26,4)="第3領域","断る・任せる・後に回す",LEFT($D26,4)="第4領域","減らす・やめる",TRUE,"判断する"))
D27: =IF($A27="","",IFS(AND($B27="重要",$C27="緊急"),"第1領域｜重要×緊急",AND($B27="重要",$C27="緊急ではない"),"第2領域｜重要×非緊急",AND($B27="重要ではない",$C27="緊急"),"第3領域｜非重要×緊急",AND($B27="重要ではない",$C27="緊急ではない"),"第4領域｜非重要×非緊急",TRUE,"未分類")) | E27: =IF($A27="","",IFS(LEFT($D27,4)="第1領域","予防・仕組み化で減らす",LEFT($D27,4)="第2領域","先に予定へ入れて増やす",LEFT($D27,4)="第3領域","断る・任せる・後に回す",LEFT($D27,4)="第4領域","減らす・やめる",TRUE,"判断する"))
D28: =IF($A28="","",IFS(AND($B28="重要",$C28="緊急"),"第1領域｜重要×緊急",AND($B28="重要",$C28="緊急ではない"),"第2領域｜重要×非緊急",AND($B28="重要ではない",$C28="緊急"),"第3領域｜非重要×緊急",AND($B28="重要ではない",$C28="緊急ではない"),"第4領域｜非重要×非緊急",TRUE,"未分類")) | E28: =IF($A28="","",IFS(LEFT($D28,4)="第1領域","予防・仕組み化で減らす",LEFT($D28,4)="第2領域","先に予定へ入れて増やす",LEFT($D28,4)="第3領域","断る・任せる・後に回す",LEFT($D28,4)="第4領域","減らす・やめる",TRUE,"判断する"))
D29: =IF($A29="","",IFS(AND($B29="重要",$C29="緊急"),"第1領域｜重要×緊急",AND($B29="重要",$C29="緊急ではない"),"第2領域｜重要×非緊急",AND($B29="重要ではない",$C29="緊急"),"第3領域｜非重要×緊急",AND($B29="重要ではない",$C29="緊急ではない"),"第4領域｜非重要×非緊急",TRUE,"未分類")) | E29: =IF($A29="","",IFS(LEFT($D29,4)="第1領域","予防・仕組み化で減らす",LEFT($D29,4)="第2領域","先に予定へ入れて増やす",LEFT($D29,4)="第3領域","断る・任せる・後に回す",LEFT($D29,4)="第4領域","減らす・やめる",TRUE,"判断する"))
D30: =IF($A30="","",IFS(AND($B30="重要",$C30="緊急"),"第1領域｜重要×緊急",AND($B30="重要",$C30="緊急ではない"),"第2領域｜重要×非緊急",AND($B30="重要ではない",$C30="緊急"),"第3領域｜非重要×緊急",AND($B30="重要ではない",$C30="緊急ではない"),"第4領域｜非重要×非緊急",TRUE,"未分類")) | E30: =IF($A30="","",IFS(LEFT($D30,4)="第1領域","予防・仕組み化で減らす",LEFT($D30,4)="第2領域","先に予定へ入れて増やす",LEFT($D30,4)="第3領域","断る・任せる・後に回す",LEFT($D30,4)="第4領域","減らす・やめる",TRUE,"判断する"))
D31: =IF($A31="","",IFS(AND($B31="重要",$C31="緊急"),"第1領域｜重要×緊急",AND($B31="重要",$C31="緊急ではない"),"第2領域｜重要×非緊急",AND($B31="重要ではない",$C31="緊急"),"第3領域｜非重要×緊急",AND($B31="重要ではない",$C31="緊急ではない"),"第4領域｜非重要×非緊急",TRUE,"未分類")) | E31: =IF($A31="","",IFS(LEFT($D31,4)="第1領域","予防・仕組み化で減らす",LEFT($D31,4)="第2領域","先に予定へ入れて増やす",LEFT($D31,4)="第3領域","断る・任せる・後に回す",LEFT($D31,4)="第4領域","減らす・やめる",TRUE,"判断する"))
A34: 入力エリア｜書きたい人が、書きたいところから、書きたい分だけ書く
A35: ブロック | B35: 問い | C35: 自分の記入 | D35: 記入例 | E35: 補足
A36: 1. 変えたい行動 | B36: いま変えたい行動を1つだけ書く | D36: 毎日15分、PCを開いてAI学習に触る | E36: 複数にしない。まず1つに絞る。
A37: 2. 止まる原因 | B37: 行動が止まりやすい原因を選ぶ | D37: 疲れている | E37: 選択式。近いものを選べばOK。
A38: 2. 止まる原因メモ | B38: なぜ止まるのかを一言で書く | D38: 仕事終わりに疲れてPCを開けない | E38: 長文不要。1行でよい。
A39: 3. 最初の2分 | B39: これなら楽にできる最小行動は？ | D39: 教材を進めず、まずCursorを開くだけ | E39: 行動のハードルを極限まで下げる。
A40: 4. if-then 必須 | B40: もし〇〇になったら、△△する | D40: もし疲れていたら、教材ではなくPCを開くだけにする | E40: やる気ではなく、反応を先に決める。
A41: 4. if-then 任意1 | B41: 必要なら追加する | D41: もしSNSを開きそうになったら、先にDiscordに一言書く | E41: 必要な人だけ。
A42: 4. if-then 任意2 | B42: 必要なら追加する | D42: もし2日空いたら、取り返そうとせず5分だけやる | E42: 必要な人だけ。
A43: 5. 考えすぎた時の戻り方 | B43: 頭がぐるぐるした時の戻り方を選ぶ | D43: 今できることを1つだけやる | E43: 不安を解決しようとせず、行動に戻る。
A44: 5. 戻り方メモ | B44: 自分用に一言で書く | D44: 完璧にやろうとしたら、今できる1行だけ進める | E44: 短くてよい。
A47: if-thenルールの説明｜迷った時・疲れた時・止まりそうな時の反応を先に決める
A48: 説明 | B48: if | C48: then | D48: 使う場面 | E48: ポイント
A49: if-thenとは「もし〇〇になったら、△△する」と事前に決める行動ルールです。 | B49: もし疲れていたら | C49: 教材を進めずPCを開くだけにする | D49: 仕事後に止まりやすい | E49: 完璧にやらない
...

Sheet 05_週報月報
A1: 05_週報月報｜最小入力で、詰まりを見つけて立て直す | W1: 週報_詰まり | X1: 状態 | Y1: 月報_状態
A2: 目的：学習者が止まりそうな原因を最小入力で可視化し、運営が必要な支援を見つけ、本人が次の一歩を決めること。学習時間は03_日々の記録から自動集計し、週報では二重入力しません。成果物URLやDemo欄は作らず、「今週やったこと」に含めます。 | W2: なし | X2: 未着手 | Y2: 未着手
W3: 時間が取れない | X3: 順調 | Y3: 進行中
A4: KPI | B4: 値 | C4: 見方 | E4: KPI | F4: 値 | G4: 見方 | I4: KPI | J4: 値 | W4: 内容が難しい | X4: 少し危ない | Y4: 完了
A5: 支援が必要な週 | B5: =COUNTIF($H$9:$H$112,"止まりそう")+COUNTIF($H$9:$H$112,"相談したい") -> 0 | C5: 状態が『止まりそう』または『相談したい』 | E5: 相談したい週 | F5: =COUNTIF($H$9:$H$112,"相談したい") -> 0 | G5: 状態が『相談したい』 | I5: 月報完了数 | J5: =COUNTIF($S$9:$S$32,"完了") -> 0 | W5: 環境構築で詰まった | X5: 止まりそう | Y5: 順調
W6: 何をすればいいか迷っている | X6: 相談したい | Y6: 少し危ない
A7: 週報｜毎週1回。入力は「今週やったこと」「詰まり」「来週の一歩」「今の状態」だけで十分。 | L7: 月報｜月1回。今月の変化・詰まり・来月の一歩だけを見る。成果物管理ではなく立て直し用。 | W7: モチベーションが落ちている | Y7: 相談したい
A8: 週 | B8: 週開始日 | C8: 週終了日 | D8: 自動:学習時間(分) | E8: 今週やったこと | F8: 詰まり | G8: 詰まりメモ | H8: 来週の一歩 | I8: 今の状態 | J8: 運営メモ | L8: 月 | M8: 月開始日 | N8: 月終了日 | O8: 自動:学習時間(分) | P8: 今月の変化 | Q8: 詰まり・支援してほしいこと | R8: 来月の一歩 | S8: 状態 | T8: 運営メモ | U8: メモ | W8: 運営に相談したい
A9: 1 | B9: 46204 | C9: 46210 | D9: =SUMIF('03_日々の記録'!$C:$C,A9,'03_日々の記録'!$E:$E) -> 44 | I9: 未着手 | L9: 1 | M9: 46204 | N9: 46234 | O9: =SUMIF('03_日々の記録'!$D:$D,L9,'03_日々の記録'!$E:$E) -> 44 | S9: 未着手
A10: 2 | B10: 46211 | C10: 46217 | D10: =SUMIF('03_日々の記録'!$C:$C,A10,'03_日々の記録'!$E:$E) -> 0 | I10: 未着手 | L10: 2 | M10: 46235 | N10: 46265 | O10: =SUMIF('03_日々の記録'!$D:$D,L10,'03_日々の記録'!$E:$E) -> 0 | S10: 未着手
A11: 3 | B11: 46218 | C11: 46224 | D11: =SUMIF('03_日々の記録'!$C:$C,A11,'03_日々の記録'!$E:$E) -> 0 | I11: 未着手 | L11: 3 | M11: 46266 | N11: 46295 | O11: =SUMIF('03_日々の記録'!$D:$D,L11,'03_日々の記録'!$E:$E) -> 0 | S11: 未着手
A12: 4 | B12: 46225 | C12: 46231 | D12: =SUMIF('03_日々の記録'!$C:$C,A12,'03_日々の記録'!$E:$E) -> 0 | I12: 未着手 | L12: 4 | M12: 46296 | N12: 46326 | O12: =SUMIF('03_日々の記録'!$D:$D,L12,'03_日々の記録'!$E:$E) -> 0 | S12: 未着手
A13: 5 | B13: 46232 | C13: 46238 | D13: =SUMIF('03_日々の記録'!$C:$C,A13,'03_日々の記録'!$E:$E) -> 0 | I13: 未着手 | L13: 5 | M13: 46327 | N13: 46356 | O13: =SUMIF('03_日々の記録'!$D:$D,L13,'03_日々の記録'!$E:$E) -> 0 | S13: 未着手
A14: 6 | B14: 46239 | C14: 46245 | D14: =SUMIF('03_日々の記録'!$C:$C,A14,'03_日々の記録'!$E:$E) -> 0 | I14: 未着手 | L14: 6 | M14: 46357 | N14: 46387 | O14: =SUMIF('03_日々の記録'!$D:$D,L14,'03_日々の記録'!$E:$E) -> 0 | S14: 未着手
A15: 7 | B15: 46246 | C15: 46252 | D15: =SUMIF('03_日々の記録'!$C:$C,A15,'03_日々の記録'!$E:$E) -> 0 | I15: 未着手 | L15: 7 | M15: 46388 | N15: 46418 | O15: =SUMIF('03_日々の記録'!$D:$D,L15,'03_日々の記録'!$E:$E) -> 0 | S15: 未着手
A16: 8 | B16: 46253 | C16: 46259 | D16: =SUMIF('03_日々の記録'!$C:$C,A16,'03_日々の記録'!$E:$E) -> 0 | I16: 未着手 | L16: 8 | M16: 46419 | N16: 46446 | O16: =SUMIF('03_日々の記録'!$D:$D,L16,'03_日々の記録'!$E:$E) -> 0 | S16: 未着手
A17: 9 | B17: 46260 | C17: 46266 | D17: =SUMIF('03_日々の記録'!$C:$C,A17,'03_日々の記録'!$E:$E) -> 0 | I17: 未着手 | L17: 9 | M17: 46447 | N17: 46477 | O17: =SUMIF('03_日々の記録'!$D:$D,L17,'03_日々の記録'!$E:$E) -> 0 | S17: 未着手
A18: 10 | B18: 46267 | C18: 46273 | D18: =SUMIF('03_日々の記録'!$C:$C,A18,'03_日々の記録'!$E:$E) -> 0 | I18: 未着手 | L18: 10 | M18: 46478 | N18: 46507 | O18: =SUMIF('03_日々の記録'!$D:$D,L18,'03_日々の記録'!$E:$E) -> 0 | S18: 未着手
A19: 11 | B19: 46274 | C19: 46280 | D19: =SUMIF('03_日々の記録'!$C:$C,A19,'03_日々の記録'!$E:$E) -> 0 | I19: 未着手 | L19: 11 | M19: 46508 | N19: 46538 | O19: =SUMIF('03_日々の記録'!$D:$D,L19,'03_日々の記録'!$E:$E) -> 0 | S19: 未着手
A20: 12 | B20: 46281 | C20: 46287 | D20: =SUMIF('03_日々の記録'!$C:$C,A20,'03_日々の記録'!$E:$E) -> 0 | I20: 未着手 | L20: 12 | M20: 46539 | N20: 46568 | O20: =SUMIF('03_日々の記録'!$D:$D,L20,'03_日々の記録'!$E:$E) -> 0 | S20: 未着手
... A32: 24 | B32: 46365 | C32: 46371 | D32: =SUMIF('03_日々の記録'!$C:$C,A32,'03_日々の記録'!$E:$E) -> 0 | I32: 未着手 | L32: 24 | M32: 46905 | N32: 46934 | O32: =SUMIF('03_日々の記録'!$D:$D,L32,'03_日々の記録'!$E:$E) -> 0 | S32: 未着手
A33: 25 | B33: 46372 | C33: 46378 | D33: =SUMIF('03_日々の記録'!$C:$C,A33,'03_日々の記録'!$E:$E) -> 0 | I33: 未着手
A34: 26 | B34: 46379 | C34: 46385 | D34: =SUMIF('03_日々の記録'!$C:$C,A34,'03_日々の記録'!$E:$E) -> 0 | I34: 未着手
A35: 27 | B35: 46386 | C35: 46392 | D35: =SUMIF('03_日々の記録'!$C:$C,A35,'03_日々の記録'!$E:$E) -> 0 | I35: 未着手
A36: 28 | B36: 46393 | C36: 46399 | D36: =SUMIF('03_日々の記録'!$C:$C,A36,'03_日々の記録'!$E:$E) -> 0 | I36: 未着手
A37: 29 | B37: 46400 | C37: 46406 | D37: =SUMIF('03_日々の記録'!$C:$C,A37,'03_日々の記録'!$E:$E) -> 0 | I37: 未着手
A38: 30 | B38: 46407 | C38: 46413 | D38: =SUMIF('03_日々の記録'!$C:$C,A38,'03_日々の記録'!$E:$E) -> 0 | I38: 未着手
A39: 31 | B39: 46414 | C39: 46420 | D39: =SUMIF('03_日々の記録'!$C:$C,A39,'03_日々の記録'!$E:$E) -> 0 | I39: 未着手
A40: 32 | B40: 46421 | C40: 46427 | D40: =SUMIF('03_日々の記録'!$C:$C,A40,'03_日々の記録'!$E:$E) -> 0 | I40: 未着手
A41: 33 | B41: 46428 | C41: 46434 | D41: =SUMIF('03_日々の記録'!$C:$C,A41,'03_日々の記録'!$E:$E) -> 0 | I41: 未着手
A42: 34 | B42: 46435 | C42: 46441 | D42: =SUMIF('03_日々の記録'!$C:$C,A42,'03_日々の記録'!$E:$E) -> 0 | I42: 未着手
A43: 35 | B43: 46442 | C43: 46448 | D43: =SUMIF('03_日々の記録'!$C:$C,A43,'03_日々の記録'!$E:$E) -> 0 | I43: 未着手
A44: 36 | B44: 46449 | C44: 46455 | D44: =SUMIF('03_日々の記録'!$C:$C,A44,'03_日々の記録'!$E:$E) -> 0 | I44: 未着手
... A112: 104 | B112: 46925 | C112: 46931 | D112: =SUMIF('03_日々の記録'!$C:$C,A112,'03_日々の記録'!$E:$E) -> 0 | I112: 未着手
